Workbook

Sheet M WAGES
A1: JOY MANPOWER SERVICE
A2: WAGES STATEMENT FOR THE MONTH OF APR -2023 WTU III
A3: S NO | B3: PUNCHING NO | C3: NAME | D3: DEPT | E3: UAN Number | F3: ESI Number | G3: D WAGES | I3: W DAYS | J3: BASIC 70% | K3: HRA 30% | L3: OT | M3: OT STIPEND | N3: F.ALLOWANCE | O3: N.ALLOWANCE | P3: ATT BONUS | Q3: GROSS | R3: PF 12% | S3: ESI 0.75% | T3: CANTEEN | U3: RENT | V3: NET AMOUNT | W3: SIGNATURE
A4: 1 | B4: 20357 | C4: MUNIYASAMY K | D4: IMD | E4: 101501794693 | F4: 5608953024 | G4: 8910 | H4: 4 | J4: =ROUND((G4/31*I4)*70%,0) -> 0 | K4: =ROUND((G4/31*I4)*30%,0) -> 0 | M4: =+ROUND(((G4/31)/8)*L4,0) -> 0 | Q4: =J4+K4+M4+N4+O4+P4 -> 0 | R4: =+J4*12% -> 0 | S4: =CEILING((Q4-P4)*0.75%,1) -> 0 | V4: =ROUND(Q4-R4-S4-T4-U4,0) -> 0
A5: TOTAL | H5: =SUM(H4:H4) -> 4 | I5: =SUM(I4:I4) -> 0 | J5: =SUM(J4:J4) -> 0 | K5: =SUM(K4:K4) -> 0 | L5: =SUM(L4:L4) -> 0 | M5: =SUM(M4:M4) -> 0 | N5: =SUM(N4:N4) -> 0 | O5: =SUM(O4:O4) -> 0 | ... V5: =SUM(V4:V4) -> 0

Sheet INVOICE
B3: Mobile - 9080776580
B4: GSTIN Number - 33AOAPR4773D1Z2
B5: INVOICE
B6: From | G6: Invoice Number | I6: 206/2026-27
B7: JOY MANPOWER SERVICE
B8: No.16, Krishna complex, Avinashi main road, | G8: Invoice Date | I8: 27/09/2026
B9: Thennampalayam, Arasur PO,
B10: Coimbatore - 641 407. | G10: PAN Number | I10: AOAPR4773D
B11: GSTIN Number : 33AOAPR4773D1Z2
B12: To | G12: SAC Code | I12: 998519
B13: Watertec India Private Limited - Unit - Ill
B14: S.F. NO 129/2, Karavali Madhapur, | G14: PF Code | I14: CB/CBE/1724259000
B15: Sulur Taluk, Coimbatore – 641668
B16: GSTIN Number : 33AAACW1645G1ZM | G16: ESIC Code | I16: 56001195190001001
B18: Particulars | I18: Rs.
B20: 1. Being the Contract Services for supply of manpower | I20: ='BREAKUP '!E10 -> 748749.03
B21: at your Factory permises from 26.08.2026 to 25.09.2026
B23: 2. CGST @ 9% on Billing Amount | I23: =+I20*9% -> 67387.413
B25: 3 .SGST @ 9% on Billing Amount | I25: =+I20*9% -> 67387.413
I27: =SUM(I20:I26) -> 883523.86
B29: TOTAL AMOUNT :- | I29: =I27 -> 883523.86
B31: ='BREAKUP '!B14:E14 -> Rupees : Eight Lakhs Eighty Three Thousand Five Hundred And Twenty Four Only /-

Sheet BREAKUP 
B2: WAGES BREAKUP FOR THE MONTH OF SEPTEMBER 2026
B4: S.NO. | C4: PARTICULARS | E4: AMOUNT
B5: 1 | C5: Being the Contract Services for supply of manpower at | E5: ='D WAGES'!T47 -> 657637
C6: your Factory permises from 26.08.2026 TO 25.09.2026
B7: 2 | C7: P.F.Employer Contribution @ 13% Rs. | D7: ='D WAGES'!K47 -> 292824 | E7: =D7*13% -> 38067.12
B8: 3 | C8: E.S.I Employer Contribution @ 3.25% Rs. | D8: ='D WAGES'!U47 -> 418052 | E8: =D8*3.25% -> 13586.69
B9: 4 | C9: Service Charges @ 6% on Gross | E9: =+E5*6% -> 39458.22
C10: TOTAL | E10: =+E9+E5+E7+E8 -> 748749.03
B11: 5 | C11: CGST @ 9% on Billing Amount | E11: =+E10*9% -> 67387.413
B12: 6 | C12: SGST @ 9% on Billing Amount | E12: =+E10*9% -> 67387.413
C13: GRAND TOTAL | E13: =+E12+E11+E10 -> 883523.86
B14: Rupees : Eight Lakhs Eighty Three Thousand Five Hundred And Twenty Four Only /-
B15: 1 | C15: Canteen Deduction | D15: ='D WAGES'!X47 -> 6240
B16: 2 | C16: Room Rent deduction | D16: ='D WAGES'!Y47 -> 0
B17: 3 | C17: ADD Room Rent (17*250) | D17: ='ROOM ALLOW'!F21 -> 4250

Sheet Sheet1
A1: WATERTEC (INDIA) PRIVATE LIMITED
A2: Coimbatore
A3: Attendance Details From 26-Dec-2025 - To 25-Jan-2026
A6: S.No | B6: EMP ID | C6: EMPLOYEE NAME | D6: CATEGORY | E6: DEPARTMENT | H6: PRESENT DAYS | I6: NFH | J6: W/Off | K6: CL | L6: PL | M6: LOP | N6: NO.OF SHIFTS PER MONTH (PRESENT) | R6: OVERTIME | S6: NO.OF DAYS WORKED OVERTIME MORE THAN 4 HRS & 8 HRS IN W/OFF | T6: NA
N7: G.SHIFT | O7: SHIFT I | P7: SHIFT II | Q7: SHIFT III
A8: 1 | B8: 20385 | C8: SAKTHI S | D8: JOY MANPOWER SERVICES | E8: Assembly | F8: =+VLOOKUP(B8,#REF!,3,0) -> #REF! | G8: =+E8=F8 -> #REF! | H8: 21 | I8: 3 | J8: 0 | K8: 0 | L8: 0 | M8: 2 | N8: 21 | O8: 0 | P8: 0 | Q8: 0 | R8: 61 | S8: 5 | T8: =P8*45 -> 0 | U8: 0 | V8: =+VLOOKUP(B8,'[1]D WAGES'!$B$4:$P$54,15,0) -> 0 | W8: =+U8-V8 -> 0
A9: 2 | B9: 21227 | C9: SANGEETHA | D9: JOY MANPOWER SERVICES | E9: Fetling | F9: =+VLOOKUP(B9,#REF!,3,0) -> #REF! | G9: =+E9=F9 -> #REF! | H9: 21 | I9: 3 | J9: 2 | K9: 0 | L9: 0 | M9: 2 | N9: 21 | O9: 0 | P9: 0 | Q9: 0 | R9: 45 | S9: 3 | T9: =P9*45 -> 0 | U9: 0 | V9: =+VLOOKUP(B9,'[1]D WAGES'!$B$4:$P$54,15,0) -> 0 | W9: =+U9-V9 -> 0
A10: 3 | B10: 21295 | C10: JAYAMARY SOOSAIYAPPAN | D10: JOY MANPOWER SERVICES | E10: Assembly | F10: =+VLOOKUP(B10,#REF!,3,0) -> #REF! | G10: =+E10=F10 -> #REF! | H10: 22 | I10: 3 | J10: 2 | K10: 0 | L10: 0 | M10: 1 | N10: 22 | O10: 0 | P10: 0 | Q10: 0 | R10: 46 | S10: 3 | T10: =P10*45 -> 0 | U10: 0 | V10: =+VLOOKUP(B10,'[1]D WAGES'!$B$4:$P$54,15,0) -> 0 | W10: =+U10-V10 -> 0
A11: 4 | B11: 21332 | C11: KAVITHA KANAGARAJ | D11: JOY MANPOWER SERVICES | E11: Assembly | F11: =+VLOOKUP(B11,#REF!,3,0) -> #REF! | G11: =+E11=F11 -> #REF! | H11: 9 | I11: 3 | J11: 5 | K11: 0 | L11: 0 | M11: 14 | N11: 9 | O11: 0 | P11: 0 | Q11: 0 | R11: 9 | S11: 0 | T11: =P11*45 -> 0 | U11: 0 | V11: =+VLOOKUP(B11,'[1]D WAGES'!$B$4:$P$54,15,0) -> 0 | W11: =+U11-V11 -> 0
A12: 6 | B12: 21481 | C12: INDHUMATHI | D12: JOY MANPOWER SERVICES | E12: Assembly | F12: =+VLOOKUP(B12,#REF!,3,0) -> #REF! | G12: =+E12=F12 -> #REF! | H12: 20 | I12: 3 | J12: 3 | K12: 0 | L12: 0 | M12: 3 | N12: 20 | O12: 0 | P12: 0 | Q12: 0 | R12: 36 | S12: 2 | T12: =P12*45 -> 0 | U12: 0 | V12: =+VLOOKUP(B12,'[1]D WAGES'!$B$4:$P$54,15,0) -> 0 | W12: =+U12-V12 -> 0
A13: 7 | B13: 21515 | C13: VANAJA | D13: JOY MANPOWER SERVICES | E13: Assembly | F13: =+VLOOKUP(B13,#REF!,3,0) -> #REF! | G13: =+E13=F13 -> #REF! | H13: 21 | I13: 3 | J13: 2 | K13: 0 | L13: 0 | M13: 2 | N13: 21 | O13: 0 | P13: 0 | Q13: 0 | R13: 45 | S13: 3 | T13: =P13*45 -> 0 | U13: 0 | V13: =+VLOOKUP(B13,'[1]D WAGES'!$B$4:$P$54,15,0) -> 0 | W13: =+U13-V13 -> 0
A14: 8 | B14: 21517 | C14: ANANTHI MUTHURAMALINGAM | D14: JOY MANPOWER SERVICES | E14: Assembly | F14: =+VLOOKUP(B14,#REF!,3,0) -> #REF! | G14: =+E14=F14 -> #REF! | H14: 18 | I14: 3 | J14: 4 | K14: 0 | L14: 0 | M14: 5 | N14: 18 | O14: 0 | P14: 0 | Q14: 0 | R14: 26 | S14: 1 | T14: =P14*45 -> 0 | U14: 0 | V14: =+VLOOKUP(B14,'[1]D WAGES'!$B$4:$P$54,15,0) -> 0 | W14: =+U14-V14 -> 0
A15: 9 | B15: 21555 | C15: PANDIAN MARUTHAN | D15: JOY MANPOWER SERVICES | E15: Stores | F15: =+VLOOKUP(B15,#REF!,3,0) -> #REF! | G15: =+E15=F15 -> #REF! | H15: 21 | I15: 3 | J15: 1 | K15: 0 | L15: 0 | M15: 2 | N15: 0 | O15: 1 | P15: 20 | Q15: 0 | R15: 127 | S15: 23 | T15: =P15*45 -> 900 | U15: =+S15*20 -> 460 | V15: =+VLOOKUP(B15,'[1]D WAGES'!$B$4:$P$54,15,0) -> 460 | W15: =+U15-V15 -> 0
A16: 10 | B16: 21588 | C16: BHUVANESHWARI | D16: JOY MANPOWER SERVICES | E16: Assembly | F16: =+VLOOKUP(B16,#REF!,3,0) -> #REF! | G16: =+E16=F16 -> #REF! | H16: 17 | I16: 3 | J16: 3 | K16: 0 | L16: 0 | M16: 6 | N16: 17 | O16: 0 | P16: 0 | Q16: 0 | R16: 33 | S16: 2 | T16: =P16*45 -> 0 | U16: 0 | V16: =+VLOOKUP(B16,'[1]D WAGES'!$B$4:$P$54,15,0) -> 0 | W16: =+U16-V16 -> 0
A17: 11 | B17: 21710 | C17: MURUGESWARI BALAJI | D17: JOY MANPOWER SERVICES | E17: Assembly | F17: =+VLOOKUP(B17,#REF!,3,0) -> #REF! | G17: =+E17=F17 -> #REF! | H17: 23 | I17: 3 | J17: 0 | K17: 0 | L17: 0 | M17: 0 | N17: 23 | O17: 0 | P17: 0 | Q17: 0 | R17: 63 | S17: 5 | T17: =P17*45 -> 0 | U17: 0 | V17: =+VLOOKUP(B17,'[1]D WAGES'!$B$4:$P$54,15,0) -> 0 | W17: =+U17-V17 -> 0
A18: 12 | B18: 21713 | C18: MUNESHWAR SOREN | D18: JOY MANPOWER SERVICES | E18: IMD | F18: =+VLOOKUP(B18,#REF!,3,0) -> #REF! | G18: =+E18=F18 -> #REF! | H18: 22 | I18: 3 | J18: 2 | K18: 0 | L18: 0 | M18: 1 | N18: 0 | O18: 12 | P18: 10 | Q18: 0 | R18: 124 | S18: 25 | T18: =P18*45 -> 450 | U18: =+S18*20 -> 500 | V18: =+VLOOKUP(B18,'[1]D WAGES'!$B$4:$P$54,15,0) -> 500 | W18: =+U18-V18 -> 0
A19: 13 | B19: 22042 | C19: GOVINDARAJ ARUMUGAM | D19: JOY MANPOWER SERVICES | E19: IMD | F19: =+VLOOKUP(B19,#REF!,3,0) -> #REF! | G19: =+E19=F19 -> #REF! | H19: 18 | I19: 3 | J19: 3 | K19: 0 | L19: 0 | M19: 5 | N19: 0 | O19: 10 | P19: 8 | Q19: 0 | R19: 81 | S19: 19 | T19: =P19*45 -> 360 | U19: =+S19*20 -> 380 | V19: =+VLOOKUP(B19,'[1]D WAGES'!$B$4:$P$54,15,0) -> 380 | W19: =+U19-V19 -> 0
A20: 14 | B20: 22050 | C20: ANITHA SURESHMUTHU | D20: JOY MANPOWER SERVICES | E20: Assembly | F20: =+VLOOKUP(B20,#REF!,3,0) -> #REF! | G20: =+E20=F20 -> #REF! | H20: 22 | I20: 3 | J20: 0 | K20: 0 | L20: 0 | M20: 1 | N20: 22 | O20: 0 | P20: 0 | Q20: 0 | R20: 62 | S20: 5 | T20: =P20*45 -> 0 | U20: 0 | V20: =+VLOOKUP(B20,'[1]D WAGES'!$B$4:$P$54,15,0) -> 0 | W20: =+U20-V20 -> 0
A21: 16 | B21: 22104 | C21: VIJAYA LAKSHMI | D21: JOY MANPOWER SERVICES | E21: Assembly | F21: =+VLOOKUP(B21,#REF!,3,0) -> #REF! | G21: =+E21=F21 -> #REF! | H21: 23 | I21: 3 | J21: 4 | K21: 0 | L21: 0 | M21: 0 | N21: 23 | O21: 0 | P21: 0 | Q21: 0 | R21: 31 | S21: 1 | T21: =P21*45 -> 0 | U21: 0 | V21: =+VLOOKUP(B21,'[1]D WAGES'!$B$4:$P$54,15,0) -> 0 | W21: =+U21-V21 -> 0
A22: 17 | B22: 22111 | C22: INDHUMATHI | D22: JOY MANPOWER SERVICES | E22: Assembly | F22: =+VLOOKUP(B22,#REF!,3,0) -> #REF! | G22: =+E22=F22 -> #REF! | H22: 18 | I22: 3 | J22: 5 | K22: 0 | L22: 0 | M22: 5 | N22: 18 | O22: 0 | P22: 0 | Q22: 0 | R22: 18 | S22: 0 | T22: =P22*45 -> 0 | U22: =+S22*20 -> 0 | V22: =+VLOOKUP(B22,'[1]D WAGES'!$B$4:$P$54,15,0) -> 0 | W22: =+U22-V22 -> 0
A23: 18 | B23: 22115 | C23: DEVI | D23: JOY MANPOWER SERVICES | E23: Assembly | F23: =+VLOOKUP(B23,#REF!,3,0) -> #REF! | G23: =+E23=F23 -> #REF! | H23: 21 | I23: 3 | J23: 3 | K23: 0 | L23: 0 | M23: 2 | N23: 21 | O23: 0 | P23: 0 | Q23: 0 | R23: 37 | S23: 2 | T23: =P23*45 -> 0 | U23: 0 | V23: =+VLOOKUP(B23,'[1]D WAGES'!$B$4:$P$54,15,0) -> 0 | W23: =+U23-V23 -> 0
A24: 19 | B24: 22133 | C24: RAMACHANDRAN | D24: JOY MANPOWER SERVICES | E24: AUTOMATION | F24: =+VLOOKUP(B24,#REF!,3,0) -> #REF! | G24: =+E24=F24 -> #REF! | H24: 21 | I24: 3 | J24: 3 | K24: 0 | L24: 0 | M24: 2 | N24: 0 | O24: 10 | P24: 11 | Q24: 0 | R24: 108 | S24: 23 | T24: =P24*45 -> 495 | U24: =+S24*20 -> 460 | V24: =+VLOOKUP(B24,'[1]D WAGES'!$B$4:$P$54,15,0) -> 460 | W24: =+U24-V24 -> 0
A25: 20 | B25: 22146 | C25: VASANTHAMNAI | D25: JOY MANPOWER SERVICES | E25: Fetling | F25: =+VLOOKUP(B25,#REF!,3,0) -> #REF! | G25: =+E25=F25 -> #REF! | H25: 23 | I25: 3 | J25: 3 | K25: 0 | L25: 0 | M25: 0 | N25: 23 | O25: 0 | P25: 0 | Q25: 0 | R25: 39 | S25: 2 | T25: =P25*45 -> 0 | V25: =+VLOOKUP(B25,'[1]D WAGES'!$B$4:$P$54,15,0) -> 0 | W25: =+U25-V25 -> 0
A26: 21 | B26: 22149 | C26: DEEPA | D26: JOY MANPOWER SERVICES | E26: Assembly | F26: =+VLOOKUP(B26,#REF!,3,0) -> #REF! | G26: =+E26=F26 -> #REF! | H26: 18 | I26: 3 | J26: 1 | K26: 0 | L26: 0 | M26: 5 | N26: 18 | O26: 0 | P26: 0 | Q26: 0 | R26: 50 | S26: 4 | T26: =P26*45 -> 0 | V26: =+VLOOKUP(B26,'[1]D WAGES'!$B$4:$P$54,15,0) -> 0 | W26: =+U26-V26 -> 0
A27: 22 | B27: 22168 | C27: T.VINITHA | D27: JOY MANPOWER SERVICES | E27: Assembly | F27: =+VLOOKUP(B27,#REF!,3,0) -> #REF! | G27: =+E27=F27 -> #REF! | H27: 18.5 | I27: 3 | J27: 4 | K27: 0 | L27: 0 | M27: 4.5 | N27: 18.5 | O27: 0 | P27: 0 | Q27: 0 | R27: 26 | S27: 1 | T27: =P27*45 -> 0 | V27: =+VLOOKUP(B27,'[1]D WAGES'!$B$4:$P$54,15,0) -> 0 | W27: =+U27-V27 -> 0
A28: 24 | B28: 22176 | C28: HEMALATHA | D28: JOY MANPOWER SERVICES | E28: Assembly | F28: =+VLOOKUP(B28,#REF!,3,0) -> #REF! | G28: =+E28=F28 -> #REF! | H28: 19 | I28: 3 | J28: 1 | K28: 0 | L28: 0 | M28: 4 | N28: 19 | O28: 0 | P28: 0 | Q28: 0 | R28: 51 | S28: 4 | T28: =P28*45 -> 0 | V28: =+VLOOKUP(B28,'[1]D WAGES'!$B$4:$P$54,15,0) -> 0 | W28: =+U28-V28 -> 0
A29: 25 | B29: 22204 | C29: SANJAY KUMAR | D29: JOY MANPOWER SERVICES | E29: IMD | F29: =+VLOOKUP(B29,#REF!,3,0) -> #REF! | G29: =+E29=F29 -> #REF! | H29: 23 | I29: 3 | J29: 5 | K29: 0 | L29: 0 | M29: 0 | N29: 0 | O29: 23 | P29: 0 | Q29: 0 | R29: 89 | S29: 22 | T29: =P29*45 -> 0 | U29: =+S29*20 -> 440 | V29: =+VLOOKUP(B29,'[1]D WAGES'!$B$4:$P$54,15,0) -> 440 | W29: =+U29-V29 -> 0
A30: 26 | B30: 22215 | C30: SUNIL SAWAYNAM | D30: JOY MANPOWER SERVICES | E30: Assembly | F30: =+VLOOKUP(B30,#REF!,3,0) -> #REF! | G30: =+E30=F30 -> #REF! | H30: 22 | I30: 3 | J30: 0 | K30: 0 | L30: 0 | M30: 1 | N30: 0 | O30: 22 | P30: 0 | Q30: 0 | R30: 133 | S30: 27 | T30: =P30*45 -> 0 | U30: =+S30*20 -> 540 | V30: =+VLOOKUP(B30,'[1]D WAGES'!$B$4:$P$54,15,0) -> 540 | W30: =+U30-V30 -> 0
A31: 27 | B31: 22217 | C31: RANJEET SAWAIYAM | D31: JOY MANPOWER SERVICES | E31: IMD | F31: =+VLOOKUP(B31,#REF!,3,0) -> #REF! | G31: =+E31=F31 -> #REF! | H31: 10 | I31: 0 | J31: 1 | K31: 0 | L31: 0 | M31: 1 | N31: 0 | O31: 4 | P31: 6 | Q31: 0 | R31: 40 | S31: 10 | T31: =P31*45 -> 270 | U31: =+S31*20 -> 200 | V31: =+VLOOKUP(B31,'[1]D WAGES'!$B$4:$P$54,15,0) -> 200 | W31: =+U31-V31 -> 0
A32: 28 | B32: 22222 | C32: HAKIM MARANDI | D32: JOY MANPOWER SERVICES | E32: IMD | F32: =+VLOOKUP(B32,#REF!,3,0) -> #REF! | G32: =+E32=F32 -> #REF! | H32: 11 | I32: 0 | J32: 0 | K32: 0 | L32: 0 | M32: 0 | N32: 0 | O32: 6 | P32: 5 | Q32: 0 | R32: 56 | S32: 12 | T32: =P32*45 -> 225 | U32: =+S32*20 -> 240 | V32: =+VLOOKUP(B32,'[1]D WAGES'!$B$4:$P$54,15,0) -> 240 | W32: =+U32-V32 -> 0
A33: 29 | B33: 22223 | C33: HARIM HEMBRAM | D33: JOY MANPOWER SERVICES | E33: IMD | F33: =+VLOOKUP(B33,#REF!,3,0) -> #REF! | G33: =+E33=F33 -> #REF! | H33: 11 | I33: 0 | J33: 0 | K33: 0 | L33: 0 | M33: 0 | N33: 0 | O33: 7 | P33: 4 | Q33: 0 | R33: 56 | S33: 12 | T33: =P33*45 -> 180 | U33: =+S33*20 -> 240 | V33: =+VLOOKUP(B33,'[1]D WAGES'!$B$4:$P$54,15,0) -> 240 | W33: =+U33-V33 -> 0
A34: 31 | B34: 22225 | C34: SANTHOSH MANJHI | D34: JOY MANPOWER SERVICES | E34: IMD | F34: =+VLOOKUP(B34,#REF!,3,0) -> #REF! | G34: =+E34=F34 -> #REF! | H34: 11 | I34: 0 | J34: 1 | K34: 0 | L34: 0 | M34: 1 | N34: 0 | O34: 4 | P34: 7 | Q34: 0 | R34: 68 | S34: 13 | T34: =P34*45 -> 315 | U34: =+S34*20 -> 260 | V34: =+VLOOKUP(B34,'[1]D WAGES'!$B$4:$P$54,15,0) -> 260 | W34: =+U34-V34 -> 0
A35: 33 | B35: 22229 | C35: PREM KUMAR | D35: JOY MANPOWER SERVICES | E35: IMD | F35: =+VLOOKUP(B35,#REF!,3,0) -> #REF! | G35: =+E35=F35 -> #REF! | H35: 22 | I35: 3 | J35: 1 | K35: 0 | L35: 0 | M35: 1 | N35: 0 | O35: 12 | P35: 10 | Q35: 0 | R35: 136 | S35: 26 | T35: =P35*45 -> 450 | U35: =+S35*20 -> 520 | V35: =+VLOOKUP(B35,'[1]D WAGES'!$B$4:$P$54,15,0) -> 520 | W35: =+U35-V35 -> 0
A36: 34 | B36: 22231 | C36: SATPATI KAIBART | D36: JOY MANPOWER SERVICES | E36: IMD | F36: =+VLOOKUP(B36,#REF!,3,0) -> #REF! | G36: =+E36=F36 -> #REF! | H36: 2 | I36: 0 | J36: 1 | K36: 0 | L36: 0 | M36: 3 | N36: 0 | O36: 0 | P36: 2 | Q36: 0 | R36: 8 | S36: 2 | T36: =P36*45 -> 90 | U36: =+S36*20 -> 40 | V36: =+VLOOKUP(B36,'[1]D WAGES'!$B$4:$P$54,15,0) -> 40 | W36: =+U36-V36 -> 0
A37: 35 | B37: 22232 | C37: MANOHAR KARAN | D37: JOY MANPOWER SERVICES | E37: IMD | F37: =+VLOOKUP(B37,#REF!,3,0) -> #REF! | G37: =+E37=F37 -> #REF! | H37: 23 | I37: 3 | J37: 1 | K37: 0 | L37: 0 | M37: 0 | N37: 0 | O37: 11 | P37: 12 | Q37: 0 | R37: 140 | S37: 27 | T37: =P37*45 -> 540 | U37: =+S37*20 -> 540 | V37: =+VLOOKUP(B37,'[1]D WAGES'!$B$4:$P$54,15,0) -> 540 | W37: =+U37-V37 -> 0
A38: 37 | B38: 22234 | C38: LAXMAN RAJAK | D38: JOY MANPOWER SERVICES | E38: IMD | F38: =+VLOOKUP(B38,#REF!,3,0) -> #REF! | G38: =+E38=F38 -> #REF! | H38: 23 | I38: 3 | J38: 1 | K38: 0 | L38: 0 | M38: 0 | N38: 0 | O38: 11 | P38: 12 | Q38: 0 | R38: 140 | S38: 27 | T38: =P38*45 -> 540 | U38: =+S38*20 -> 540 | V38: =+VLOOKUP(B38,'[1]D WAGES'!$B$4:$P$54,15,0) -> 540 | W38: =+U38-V38 -> 0
A39: 39 | B39: 22240 | C39: MOHAN TUTI | D39: JOY MANPOWER SERVICES | E39: HK | F39: =+VLOOKUP(B39,#REF!,3,0) -> #REF! | G39: =+E39=F39 -> #REF! | H39: 2 | I39: 0 | J39: 1 | K39: 0 | L39: 0 | M39: 3 | N39: 0 | O39: 2 | P39: 0 | Q39: 0 | R39: 4 | S39: 0 | T39: =P39*45 -> 0 | U39: =+S39*20 -> 0 | V39: =+VLOOKUP(B39,'[1]D WAGES'!$B$4:$P$54,15,0) -> 0 | W39: =+U39-V39 -> 0
A40: 40 | B40: 22241 | C40: ANNALAKSHMI | D40: JOY MANPOWER SERVICES | E40: Assembly | F40: =+VLOOKUP(B40,#REF!,3,0) -> #REF! | G40: =+E40=F40 -> #REF! | H40: 21.5 | I40: 3 | J40: 3 | K40: 0 | L40: 0 | M40: 1.5 | N40: 21.5 | O40: 0 | P40: 0 | Q40: 0 | R40: 17 | S40: 2 | T40: =P40*45 -> 0 | V40: =+VLOOKUP(B40,'[1]D WAGES'!$B$4:$P$54,15,0) -> 0 | W40: =+U40-V40 -> 0
A41: 41 | B41: 22242 | C41: SELVI S | D41: JOY MANPOWER SERVICES | E41: Assembly | F41: =+VLOOKUP(B41,#REF!,3,0) -> #REF! | G41: =+E41=F41 -> #REF! | H41: 21 | I41: 3 | J41: 3 | K41: 0 | L41: 0 | M41: 2 | N41: 21 | O41: 0 | P41: 0 | Q41: 0 | R41: 40 | S41: 2 | T41: =P41*45 -> 0 | V41: =+VLOOKUP(B41,'[1]D WAGES'!$B$4:$P$54,15,0) -> 0 | W41: =+U41-V41 -> 0
A42: 43 | B42: 22248 | C42: POONGODI K | D42: JOY MANPOWER SERVICES | E42: Assembly | F42: =+VLOOKUP(B42,#REF!,3,0) -> #REF! | G42: =+E42=F42 -> #REF! | H42: 22 | I42: 3 | J42: 1 | K42: 0 | L42: 0 | M42: 1 | N42: 22 | O42: 0 | P42: 0 | Q42: 0 | R42: 55 | S42: 4 | T42: =P42*45 -> 0 | V42: =+VLOOKUP(B42,'[1]D WAGES'!$B$4:$P$54,15,0) -> 0 | W42: =+U42-V42 -> 0
...

Sheet Sheet2
A1: WATERTEC (INDIA) PRIVATE LIMITED
A2: Booking Report - 26-Dec-2025 To - 25-Jan-2026
A5: S.No | B5: Employee No | C5: Name | D5: Unit | E5: Dept | F5: Category | G5: Location | H5: Contractor | I5: LUNCH | J5: Total | K5: total
A6: 1 | B6: 21295 | C6: JAYAMARY SOOSAIYAPPAN | D6: UNIT-3 | E6: Assembly | F6: JOY MANPOWER SERVICES | G6: NA | H6: JOY MANPOWER SERVICES | I6: 2 | J6: 2 | K6: 40
A7: 2 | B7: 21481 | C7: INDHUMATHI | D7: UNIT-3 | E7: Assembly | F7: JOY MANPOWER SERVICES | G7: NA | H7: JOY MANPOWER SERVICES | I7: 2 | J7: 2 | K7: 40
A8: 3 | B8: 21713 | C8: MUNESHWAR SOREN | D8: UNIT-3 | E8: IMD | F8: JOY MANPOWER SERVICES | G8: NA | H8: JOY MANPOWER SERVICES | I8: 15 | J8: 15 | K8: 300
A9: 4 | B9: 22042 | C9: GOVINDARAJ ARUMUGAM | D9: UNIT-3 | E9: IMD | F9: JOY MANPOWER SERVICES | G9: NA | H9: JOY MANPOWER SERVICES | I9: 11 | J9: 11 | K9: 220
A10: 5 | B10: 22104 | C10: VIJAYA LAKSHMI | D10: UNIT-3 | E10: Assembly | F10: JOY MANPOWER SERVICES | G10: NA | H10: JOY MANPOWER SERVICES | I10: 1 | J10: 1 | K10: 20
A11: 6 | B11: 22133 | C11: RAMACHANDRAN | D11: UNIT-3 | E11: AUTOMATION | F11: JOY MANPOWER SERVICES | G11: NA | H11: JOY MANPOWER SERVICES | I11: 11 | J11: 11 | K11: 220
A12: 7 | B12: 22204 | C12: SANJAY KUMAR | D12: UNIT-3 | E12: IMD | F12: JOY MANPOWER SERVICES | G12: NA | H12: JOY MANPOWER SERVICES | I12: 23 | J12: 23 | K12: 460
A13: 8 | B13: 22215 | C13: SUNIL SAWAYNAM | D13: UNIT-3 | E13: Assembly | F13: JOY MANPOWER SERVICES | G13: NA | H13: JOY MANPOWER SERVICES | I13: 27 | J13: 27 | K13: 540
A14: 9 | B14: 22217 | C14: RANJEET SAWAIYAM | D14: UNIT-3 | E14: IMD | F14: JOY MANPOWER SERVICES | G14: NA | H14: JOY MANPOWER SERVICES | I14: 4 | J14: 4 | K14: 80
A15: 10 | B15: 22222 | C15: HAKIM MARANDI | D15: UNIT-3 | E15: IMD | F15: JOY MANPOWER SERVICES | G15: NA | H15: JOY MANPOWER SERVICES | I15: 7 | J15: 7 | K15: 140
A16: 11 | B16: 22223 | C16: HARIM HEMBRAM | D16: UNIT-3 | E16: IMD | F16: JOY MANPOWER SERVICES | G16: NA | H16: JOY MANPOWER SERVICES | I16: 7 | J16: 7 | K16: 140
A17: 12 | B17: 22225 | C17: SANTHOSH MANJHI | D17: UNIT-3 | E17: IMD | F17: JOY MANPOWER SERVICES | G17: NA | H17: JOY MANPOWER SERVICES | I17: 3 | J17: 3 | K17: 60
... A30: 25 | B30: 22259 | C30: NITHEESH KUMAR | D30: UNIT-3 | E30: AUTOMATION | F30: JOY MANPOWER SERVICES | G30: NA | H30: JOY MANPOWER SERVICES | I30: 8 | J30: 8 | K30: 160
A32: Total | I32: 242 | J32: 242 | K32: 4840

Sheet Sheet3
A1: WATERTEC (INDIA) PRIVATE LIMITED
A2: Coimbatore
A3: Over Time Report From 26-Dec-2025 - To 25-Jan-2026
AN5: FA
A6: S.No | B6: EMP ID | C6: EMPLOYEE NAME | D6: CATEGORY | E6: DEPARTMENT | F6: SUB-CATEGORY | G6: 26 | H6: 27 | I6: 28 | J6: 29 | K6: 30 | L6: 31 | M6: 1 | N6: 2 | O6: 3 | P6: 4 | Q6: 5 | R6: 6 | S6: 7 | T6: 8 | U6: 9 | V6: 10 | W6: 11 | X6: 12 | Y6: 13 | Z6: 14 | AA6: 15 | AB6: 16 | AC6: 17 | AD6: 18 | AE6: 19 | AF6: 20 | AG6: 21 | AH6: 22 | AI6: 23 | AJ6: 24 | AK6: 25 | AL6: TOTAL OT HR | AM6: NO. OF TIMES OT - 4 HRS AND ABOVE
A7: 1 | B7: 20385 | C7: SAKTHI S | D7: JOY MANPOWER SERVICES | E7: Assembly | F7: NA | G7: 1 | H7: 1 | I7: 8 | J7: 1 | K7: 1 | L7: 1 | N7: 1 | O7: 1 | P7: 8 | Q7: 1 | R7: 1 | S7: 1 | T7: 1 | W7: 8 | X7: 1 | Y7: 1 | Z7: 1 | AC7: 1 | AD7: 8 | AE7: 1 | AF7: 1 | AG7: 1 | AH7: 1 | AI7: 1 | AJ7: 1 | AK7: 8 | AL7: 61 | AM7: 5
A8: 2 | B8: 21227 | C8: SANGEETHA | D8: JOY MANPOWER SERVICES | E8: Fetling | F8: NA | G8: 1 | H8: 1 | J8: 1 | K8: 1 | L8: 1 | N8: 1 | O8: 1 | P8: 8 | Q8: 1 | R8: 1 | S8: 1 | T8: 1 | V8: 1 | X8: 1 | Y8: 1 | Z8: 1 | AC8: 1 | AD8: 8 | AE8: 1 | AG8: 1 | AH8: 1 | AI8: 1 | AJ8: 1 | AK8: 8 | AL8: 45 | AM8: 3
A9: 3 | B9: 21295 | C9: JAYAMARY SOOSAIYAPPAN | D9: JOY MANPOWER SERVICES | E9: Assembly | F9: NA | G9: 1 | H9: 1 | J9: 1 | K9: 1 | L9: 1 | N9: 1 | O9: 1 | P9: 8 | Q9: 1 | R9: 1 | S9: 1 | T9: 1 | U9: 1 | V9: 1 | W9: 8 | X9: 1 | Y9: 1 | Z9: 1 | AC9: 1 | AD9: 8 | AE9: 1 | AF9: 1 | AG9: 1 | AH9: 1 | AI9: 1 | AL9: 46 | AM9: 3
A10: 4 | B10: 21332 | C10: KAVITHA KANAGARAJ | D10: JOY MANPOWER SERVICES | E10: Assembly | F10: NA | R10: 1 | S10: 1 | T10: 1 | U10: 1 | V10: 1 | X10: 1 | Y10: 1 | AE10: 1 | AF10: 1 | AL10: 9 | AM10: 0 | AN10: =AM10*20 -> 0
A11: 5 | B11: 21481 | C11: INDHUMATHI | D11: JOY MANPOWER SERVICES | E11: Assembly | F11: NA | G11: 1 | H11: 1 | K11: 1 | L11: 1 | O11: 1 | P11: 8 | Q11: 1 | R11: 1 | S11: 1 | T11: 1 | U11: 1 | V11: 1 | W11: 8 | Y11: 1 | Z11: 1 | AC11: 1 | AE11: 1 | AF11: 1 | AG11: 1 | AH11: 1 | AI11: 1 | AJ11: 1 | AL11: 36 | AM11: 2
A12: 6 | B12: 21515 | C12: VANAJA | D12: JOY MANPOWER SERVICES | E12: Assembly | F12: NA | G12: 1 | H12: 1 | I12: 8 | J12: 1 | K12: 1 | L12: 1 | N12: 1 | O12: 1 | P12: 8 | Q12: 1 | R12: 1 | S12: 1 | T12: 1 | V12: 1 | X12: 1 | Y12: 1 | Z12: 1 | AE12: 1 | AF12: 1 | AG12: 1 | AH12: 1 | AI12: 1 | AJ12: 1 | AK12: 8 | AL12: 45 | AM12: 3
A13: 7 | B13: 21517 | C13: ANANTHI MUTHURAMALINGAM | D13: JOY MANPOWER SERVICES | E13: Assembly | F13: NA | G13: 1 | H13: 1 | J13: 1 | K13: 1 | L13: 1 | N13: 1 | Q13: 1 | R13: 1 | X13: 1 | Y13: 1 | Z13: 1 | AC13: 1 | AE13: 1 | AF13: 1 | AG13: 1 | AH13: 1 | AI13: 1 | AJ13: 1 | AK13: 8 | AL13: 26 | AM13: 1
A14: 8 | B14: 21555 | C14: PANDIAN MARUTHAN | D14: JOY MANPOWER SERVICES | E14: Stores | F14: NA | G14: 4 | J14: 4 | K14: 4 | L14: 4 | N14: 4 | O14: 4 | P14: 10.5 | Q14: 4 | R14: 4 | S14: 4 | T14: 4 | U14: 4 | V14: 4 | W14: 11.5 | X14: 4 | Y14: 3 | AC14: 4 | AD14: 12 | AE14: 4 | AF14: 4 | AG14: 4 | AH14: 4 | AI14: 2 | AJ14: 4 | AK14: 12 | AL14: 127 | AM14: 23 | AN14: =AM14*20 -> 460
A15: 9 | B15: 21588 | C15: BHUVANESHWARI | D15: JOY MANPOWER SERVICES | E15: Assembly | F15: NA | G15: 1 | H15: 1 | I15: 8 | J15: 1 | K15: 1 | N15: 1 | O15: 1 | P15: 8 | R15: 1 | S15: 1 | T15: 1 | V15: 1 | X15: 1 | Y15: 1 | Z15: 1 | AE15: 1 | AF15: 1 | AI15: 1 | AJ15: 1 | AL15: 33 | AM15: 2
A16: 10 | B16: 21710 | C16: MURUGESWARI BALAJI | D16: JOY MANPOWER SERVICES | E16: Assembly | F16: NA | G16: 1 | H16: 1 | I16: 8 | J16: 1 | K16: 1 | L16: 1 | N16: 1 | O16: 1 | P16: 8 | Q16: 1 | R16: 1 | S16: 1 | T16: 1 | U16: 1 | V16: 1 | W16: 8 | X16: 1 | Y16: 1 | Z16: 1 | AC16: 1 | AD16: 8 | AE16: 1 | AF16: 1 | AG16: 1 | AH16: 1 | AI16: 1 | AJ16: 1 | AK16: 8 | AL16: 63 | AM16: 5
A17: 11 | B17: 21713 | C17: MUNESHWAR SOREN | D17: JOY MANPOWER SERVICES | E17: IMD | F17: NA | G17: 4 | H17: 4 | J17: 4 | K17: 4 | L17: 4 | N17: 4 | O17: 4 | P17: 12 | Q17: 4 | R17: 4 | S17: 4 | T17: 4 | U17: 4 | V17: 4 | X17: 4 | Y17: 4 | AC17: 4 | AD17: 12 | AE17: 4 | AF17: 4 | AG17: 4 | AH17: 4 | AI17: 4 | AJ17: 4 | AK17: 12 | AL17: 124 | AM17: 25 | AN17: =AM17*20 -> 500
A18: 12 | B18: 22042 | C18: GOVINDARAJ ARUMUGAM | D18: JOY MANPOWER SERVICES | E18: IMD | F18: NA | H18: 4 | J18: 4 | K18: 4 | N18: 4 | O18: 4 | P18: 9 | Q18: 4 | R18: 4 | S18: 4 | T18: 4 | U18: 4 | X18: 4 | Y18: 4 | AE18: 4 | AF18: 4 | AG18: 4 | AH18: 4 | AI18: 4 | AJ18: 4 | AL18: 81 | AM18: 19 | AN18: =AM18*20 -> 380
A19: 13 | B19: 22050 | C19: ANITHA SURESHMUTHU | D19: JOY MANPOWER SERVICES | E19: Assembly | F19: NA | G19: 1 | H19: 1 | I19: 8 | J19: 1 | K19: 1 | L19: 1 | N19: 1 | O19: 1 | P19: 8 | Q19: 1 | R19: 1 | T19: 1 | U19: 1 | V19: 1 | W19: 8 | X19: 1 | Y19: 1 | Z19: 1 | AC19: 1 | AD19: 8 | AE19: 1 | AF19: 1 | AG19: 1 | AH19: 1 | AI19: 1 | AJ19: 1 | AK19: 8 | AL19: 62 | AM19: 5
A20: 14 | B20: 22104 | C20: VIJAYA LAKSHMI | D20: JOY MANPOWER SERVICES | E20: Assembly | F20: NA | G20: 1 | H20: 1 | I20: 8 | J20: 1 | K20: 1 | L20: 1 | N20: 1 | O20: 1 | Q20: 1 | R20: 1 | S20: 1 | T20: 1 | U20: 1 | V20: 1 | X20: 1 | Y20: 1 | Z20: 1 | AC20: 1 | AE20: 1 | AF20: 1 | AG20: 1 | AH20: 1 | AI20: 1 | AJ20: 1 | AL20: 31 | AM20: 1
A21: 15 | B21: 22111 | C21: INDHUMATHI | D21: JOY MANPOWER SERVICES | E21: Assembly | F21: NA | G21: 1 | H21: 1 | J21: 1 | N21: 1 | O21: 1 | Q21: 1 | R21: 1 | S21: 1 | T21: 1 | U21: 1 | V21: 1 | X21: 1 | AE21: 1 | AF21: 1 | AG21: 1 | AH21: 1 | AI21: 1 | AJ21: 1 | AL21: 18 | AM21: 0 | AN21: =AM21*20 -> 0
A22: 16 | B22: 22115 | C22: DEVI | D22: JOY MANPOWER SERVICES | E22: Assembly | F22: NA | G22: 1 | H22: 1 | I22: 8 | J22: 1 | K22: 1 | L22: 1 | N22: 1 | O22: 1 | P22: 8 | Q22: 1 | R22: 1 | S22: 1 | T22: 1 | U22: 1 | V22: 1 | X22: 1 | Y22: 1 | Z22: 1 | AC22: 1 | AE22: 1 | AF22: 1 | AG22: 1 | AH22: 1 | AL22: 37 | AM22: 2
A23: 17 | B23: 22133 | C23: RAMACHANDRAN | D23: JOY MANPOWER SERVICES | E23: AUTOMATION | F23: NA | G23: 4 | H23: 4 | J23: 4 | K23: 4 | L23: 4 | N23: 4 | O23: 4 | Q23: 4 | R23: 4 | S23: 4 | T23: 4 | U23: 4 | V23: 4 | W23: 12 | X23: 4 | Y23: 4 | AE23: 4 | AF23: 4 | AG23: 4 | AH23: 4 | AI23: 4 | AJ23: 4 | AK23: 12 | AL23: 108 | AM23: 23 | AN23: =AM23*20 -> 460
A24: 18 | B24: 22146 | C24: VASANTHAMNAI | D24: JOY MANPOWER SERVICES | E24: Fetling | F24: NA | G24: 1 | H24: 1 | J24: 1 | K24: 1 | N24: 1 | O24: 1 | Q24: 1 | R24: 1 | S24: 1 | T24: 1 | U24: 1 | V24: 1 | W24: 8 | X24: 1 | Y24: 1 | Z24: 1 | AC24: 1 | AE24: 1 | AF24: 1 | AG24: 1 | AH24: 1 | AI24: 1 | AJ24: 1 | AK24: 8 | AL24: 39 | AM24: 2
A25: 19 | B25: 22149 | C25: DEEPA | D25: JOY MANPOWER SERVICES | E25: Assembly | F25: NA | G25: 1 | H25: 1 | J25: 1 | K25: 1 | N25: 1 | O25: 1 | P25: 8 | Q25: 1 | R25: 1 | S25: 1 | T25: 1 | U25: 1 | V25: 1 | W25: 8 | Y25: 1 | Z25: 1 | AD25: 8 | AE25: 1 | AH25: 1 | AI25: 1 | AJ25: 1 | AK25: 8 | AL25: 50 | AM25: 4
A26: 20 | B26: 22168 | C26: T.VINITHA | D26: JOY MANPOWER SERVICES | E26: Assembly | F26: NA | G26: 1 | H26: 1 | J26: 1 | N26: 1 | R26: 1 | S26: 1 | T26: 1 | U26: 1 | V26: 1 | W26: 8 | X26: 1 | Y26: 1 | Z26: 1 | AC26: 1 | AE26: 1 | AF26: 1 | AG26: 1 | AH26: 1 | AI26: 1 | AL26: 26 | AM26: 1
A27: 21 | B27: 22176 | C27: HEMALATHA | D27: JOY MANPOWER SERVICES | E27: Assembly | F27: NA | G27: 1 | H27: 1 | I27: 8 | J27: 1 | K27: 1 | L27: 1 | N27: 1 | O27: 1 | P27: 8 | Q27: 1 | R27: 1 | S27: 1 | T27: 1 | U27: 1 | V27: 1 | W27: 8 | X27: 1 | Y27: 1 | Z27: 1 | AG27: 1 | AI27: 1 | AJ27: 1 | AK27: 8 | AL27: 51 | AM27: 4
A28: 22 | B28: 22204 | C28: SANJAY KUMAR | D28: JOY MANPOWER SERVICES | E28: IMD | F28: NA | G28: 4 | H28: 4 | J28: 4 | K28: 4 | L28: 4 | N28: 4 | O28: 4 | Q28: 4 | R28: 4 | S28: 4 | T28: 4 | U28: 1 | V28: 4 | X28: 4 | Y28: 4 | Z28: 4 | AC28: 4 | AE28: 4 | AF28: 4 | AG28: 4 | AH28: 4 | AI28: 4 | AJ28: 4 | AL28: 89 | AM28: 22 | AN28: =AM28*20 -> 440
A29: 23 | B29: 22215 | C29: SUNIL SAWAYNAM | D29: JOY MANPOWER SERVICES | E29: Assembly | F29: NA | G29: 4 | H29: 4 | I29: 9 | J29: 4 | K29: 4 | L29: 4 | N29: 4 | O29: 4 | P29: 9 | Q29: 4 | R29: 4 | S29: 4 | U29: 4 | V29: 4 | W29: 9 | X29: 4 | Y29: 4 | Z29: 4 | AC29: 4 | AD29: 9 | AE29: 4 | AF29: 4 | AG29: 4 | AH29: 4 | AI29: 4 | AJ29: 4 | AK29: 9 | AL29: 133 | AM29: 27 | AN29: =AM29*20 -> 540
A30: 24 | B30: 22217 | C30: RANJEET SAWAIYAM | D30: JOY MANPOWER SERVICES | E30: IMD | F30: NA | G30: 4 | H30: 4 | K30: 4 | L30: 4 | N30: 4 | O30: 4 | Q30: 4 | R30: 4 | S30: 4 | T30: 4 | AL30: 40 | AM30: 10 | AN30: =AM30*20 -> 200
A31: 25 | B31: 22222 | C31: HAKIM MARANDI | D31: JOY MANPOWER SERVICES | E31: IMD | F31: NA | G31: 4 | H31: 4 | I31: 12 | J31: 4 | K31: 4 | L31: 4 | N31: 4 | O31: 4 | R31: 4 | S31: 4 | T31: 4 | U31: 4 | AL31: 56 | AM31: 12 | AN31: =AM31*20 -> 240
A32: 26 | B32: 22223 | C32: HARIM HEMBRAM | D32: JOY MANPOWER SERVICES | E32: IMD | F32: NA | G32: 4 | H32: 4 | I32: 12 | J32: 4 | K32: 4 | L32: 4 | N32: 4 | Q32: 4 | R32: 4 | S32: 4 | T32: 4 | U32: 4 | AL32: 56 | AM32: 12 | AN32: =AM32*20 -> 240
A33: 27 | B33: 22225 | C33: SANTHOSH MANJHI | D33: JOY MANPOWER SERVICES | E33: IMD | F33: NA | G33: 4 | H33: 4 | J33: 4 | L33: 4 | N33: 4 | O33: 4 | P33: 12 | Q33: 4 | S33: 4 | T33: 4 | U33: 4 | V33: 4 | W33: 12 | AL33: 68 | AM33: 13 | AN33: =AM33*20 -> 260
A34: 28 | B34: 22229 | C34: PREM KUMAR | D34: JOY MANPOWER SERVICES | E34: IMD | F34: NA | G34: 4 | H34: 4 | J34: 4 | K34: 4 | L34: 4 | N34: 4 | O34: 4 | P34: 12 | Q34: 4 | R34: 4 | S34: 4 | T34: 4 | U34: 4 | V34: 4 | W34: 12 | X34: 4 | Y34: 4 | AC34: 4 | AD34: 12 | AE34: 4 | AF34: 4 | AG34: 4 | AH34: 4 | AI34: 4 | AJ34: 4 | AK34: 12 | AL34: 136 | AM34: 26 | AN34: =AM34*20 -> 520
A35: 29 | B35: 22231 | C35: SATPATI KAIBART | D35: JOY MANPOWER SERVICES | E35: IMD | F35: NA | G35: 4 | H35: 4 | AL35: 8 | AM35: 2 | AN35: =AM35*20 -> 40
A36: 30 | B36: 22232 | C36: MANOHAR KARAN | D36: JOY MANPOWER SERVICES | E36: IMD | F36: NA | G36: 4 | H36: 4 | I36: 12 | J36: 4 | K36: 4 | L36: 4 | N36: 4 | O36: 4 | Q36: 4 | R36: 4 | S36: 4 | T36: 4 | U36: 4 | V36: 4 | W36: 12 | X36: 4 | Y36: 4 | Z36: 4 | AC36: 4 | AD36: 12 | AE36: 4 | AF36: 4 | AG36: 4 | AH36: 4 | AI36: 4 | AJ36: 4 | AK36: 12 | AL36: 140 | AM36: 27 | AN36: =AM36*20 -> 540
A37: 31 | B37: 22234 | C37: LAXMAN RAJAK | D37: JOY MANPOWER SERVICES | E37: IMD | F37: NA | G37: 4 | H37: 4 | I37: 12 | J37: 4 | K37: 4 | L37: 4 | N37: 4 | O37: 4 | Q37: 4 | R37: 4 | S37: 4 | T37: 4 | U37: 4 | V37: 4 | W37: 12 | X37: 4 | Y37: 4 | Z37: 4 | AC37: 4 | AD37: 12 | AE37: 4 | AF37: 4 | AG37: 4 | AH37: 4 | AI37: 4 | AJ37: 4 | AK37: 12 | AL37: 140 | AM37: 27 | AN37: =AM37*20 -> 540
A38: 32 | B38: 22240 | C38: MOHAN TUTI | D38: JOY MANPOWER SERVICES | E38: HK | F38: NA | G38: 2 | H38: 2 | AL38: 4 | AM38: 0 | AN38: =AM38*20 -> 0
A39: 33 | B39: 22241 | C39: ANNALAKSHMI | D39: JOY MANPOWER SERVICES | E39: Assembly | F39: NA | I39: 8 | P39: 8 | AL39: 17 | AM39: 2
A40: 34 | B40: 22242 | C40: SELVI S | D40: JOY MANPOWER SERVICES | E40: Assembly | F40: NA | G40: 1 | H40: 1 | J40: 1 | K40: 1 | L40: 1 | N40: 1 | O40: 1 | P40: 8 | Q40: 1 | R40: 1 | T40: 1 | U40: 1 | X40: 1 | Y40: 1 | Z40: 1 | AE40: 1 | AF40: 1 | AG40: 2 | AH40: 2 | AI40: 2 | AJ40: 2 | AK40: 8 | AL40: 40 | AM40: 2
A41: 35 | B41: 22248 | C41: POONGODI K | D41: JOY MANPOWER SERVICES | E41: Assembly | F41: NA | G41: 1 | H41: 1 | I41: 8 | J41: 1 | K41: 1 | N41: 1 | O41: 1 | P41: 8 | Q41: 1 | R41: 1 | S41: 1 | T41: 1 | U41: 1 | V41: 1 | W41: 8 | X41: 1 | Y41: 1 | Z41: 1 | AE41: 1 | AF41: 1 | AG41: 1 | AH41: 1 | AI41: 1 | AJ41: 1 | AK41: 8 | AL41: 55 | AM41: 4
...

Sheet D WAGES
A2: JOY MANPOWER SERVICE WAGES FOR THE MONTH OF SEPTEMBER 2026
A3: S NO | B3: PUNCHING NO | C3: NAME | D3: DEPT | E3: UAN Number | F3: ESI Number | G3: D WAGES | H3: W DAYS | I3: NFH | J3: PAY DAYS | K3: BASIC 55% | L3: HRA 45% | M3: Wages | N3: OT | O3: OT STIPEND | P3: F.ALLOW | Q3: N.ALLOW | R3: ATTN BONUS | S3: ARREARS | T3: GROSS | U3: ESI WAGES | V3: PF 12% | W3: ESI 0.75% | X3: CANTEEN | Y3: RENT | Z3: OTHER DED | AA3: NET AMOUNT | AB3: SIGNATURE
A4: 1 | B4: 20385 | C4: SAKTHI S | D4: Assembly | E4: 101432021832 | F4: 5608897715 | G4: 605 | H4: 25 | I4: 0 | J4: =H4+I4 -> 25 | K4: =ROUND((G4*(J4))*55%,0) -> 8319 | L4: =ROUND((G4*(J4))*45%,0) -> 6806 | M4: =K4+L4 -> 15125 | N4: 0 | O4: =ROUND((+G4*55%/8*2)*N4,0) -> 0 | P4: 0 | Q4: 0 | R4: 0 | T4: =ROUND(K4+L4+O4+P4+Q4+R4+S4,0) -> 15125 | U4: =T4-L4 -> 8319 | V4: =ROUND(+K4*12%,0) -> 998 | W4: =CEILING(U4*0.75%,1) -> 63 | X4: 0 | AA4: =ROUND(T4-X4-Y4-V4-W4-Z4,0) -> 14064
A5: =A4+1 -> 2 | B5: 21332 | C5: KAVITHA KANAGARAJ | D5: Assembly | E5: 101720171633 | F5: 5608950778 | G5: 605 | H5: 18 | I5: 0 | J5: =H5+I5 -> 18 | K5: =ROUND((G5*(J5))*55%,0) -> 5990 | L5: =ROUND((G5*(J5))*45%,0) -> 4901 | M5: =K5+L5 -> 10891 | N5: 0 | O5: =ROUND((+G5*55%/8*2)*N5,0) -> 0 | P5: 0 | Q5: 0 | R5: 0 | T5: =ROUND(K5+L5+O5+P5+Q5+R5+S5,0) -> 10891 | U5: =T5-L5 -> 5990 | V5: =ROUND(+K5*12%,0) -> 719 | W5: =CEILING(U5*0.75%,1) -> 45 | X5: 0 | AA5: =ROUND(T5-X5-Y5-V5-W5-Z5,0) -> 10127
A6: =A5+1 -> 3 | B6: 21481 | C6: INDHUMATHI | D6: Assembly | E6: 101884388735 | F6: 5609350784 | G6: 605 | H6: 23 | I6: 0 | J6: =H6+I6 -> 23 | K6: =ROUND((G6*(J6))*55%,0) -> 7653 | L6: =ROUND((G6*(J6))*45%,0) -> 6262 | M6: =K6+L6 -> 13915 | N6: 0 | O6: =ROUND((+G6*55%/8*2)*N6,0) -> 0 | P6: 0 | Q6: 0 | R6: 0 | T6: =ROUND(K6+L6+O6+P6+Q6+R6+S6,0) -> 13915 | U6: =T6-L6 -> 7653 | V6: =ROUND(+K6*12%,0) -> 918 | W6: =CEILING(U6*0.75%,1) -> 58 | X6: 20 | AA6: =ROUND(T6-X6-Y6-V6-W6-Z6,0) -> 12919
A7: =A6+1 -> 4 | B7: 21515 | C7: VANAJA | D7: Assembly | E7: 101889532368 | F7: 5609723095 | G7: 605 | H7: 24 | I7: 0 | J7: =H7+I7 -> 24 | K7: =ROUND((G7*(J7))*55%,0) -> 7986 | L7: =ROUND((G7*(J7))*45%,0) -> 6534 | M7: =K7+L7 -> 14520 | N7: 0 | O7: =ROUND((+G7*55%/8*2)*N7,0) -> 0 | P7: 0 | Q7: 0 | R7: 0 | T7: =ROUND(K7+L7+O7+P7+Q7+R7+S7,0) -> 14520 | U7: =T7-L7 -> 7986 | V7: =ROUND(+K7*12%,0) -> 958 | W7: =CEILING(U7*0.75%,1) -> 60 | X7: 20 | AA7: =ROUND(T7-X7-Y7-V7-W7-Z7,0) -> 13482
A8: =A7+1 -> 5 | B8: 21517 | C8: ANANTHI MUTHURAMALINGAM | D8: Assembly | E8: 101763385167 | F8: 5609761587 | G8: 605 | H8: 24 | I8: 0 | J8: =H8+I8 -> 24 | K8: =ROUND((G8*(J8))*55%,0) -> 7986 | L8: =ROUND((G8*(J8))*45%,0) -> 6534 | M8: =K8+L8 -> 14520 | N8: 0 | O8: =ROUND((+G8*55%/8*2)*N8,0) -> 0 | P8: 0 | Q8: 0 | R8: 0 | T8: =ROUND(K8+L8+O8+P8+Q8+R8+S8,0) -> 14520 | U8: =T8-L8 -> 7986 | V8: =ROUND(+K8*12%,0) -> 958 | W8: =CEILING(U8*0.75%,1) -> 60 | X8: 0 | AA8: =ROUND(T8-X8-Y8-V8-W8-Z8,0) -> 13502
A9: =A8+1 -> 6 | B9: 21710 | C9: MURUGESWARI BALAJI | D9: Assembly | E9: 101760758089 | F9: 5610287527 | G9: 605 | H9: 25 | I9: 0 | J9: =H9+I9 -> 25 | K9: =ROUND((G9*(J9))*55%,0) -> 8319 | L9: =ROUND((G9*(J9))*45%,0) -> 6806 | M9: =K9+L9 -> 15125 | N9: 0 | O9: =ROUND((+G9*55%/8*2)*N9,0) -> 0 | P9: 0 | Q9: 0 | R9: 0 | T9: =ROUND(K9+L9+O9+P9+Q9+R9+S9,0) -> 15125 | U9: =T9-L9 -> 8319 | V9: =ROUND(+K9*12%,0) -> 998 | W9: =CEILING(U9*0.75%,1) -> 63 | X9: 0 | AA9: =ROUND(T9-X9-Y9-V9-W9-Z9,0) -> 14064
A10: =A9+1 -> 7 | B10: 21713 | C10: MUNESHWAR SOREN | D10: IMD | E10: 101970318746 | F10: 5610093217 | G10: 605 | H10: 23 | I10: 0 | J10: =H10+I10 -> 23 | K10: =ROUND((G10*(J10))*55%,0) -> 7653 | L10: =ROUND((G10*(J10))*45%,0) -> 6262 | M10: =K10+L10 -> 13915 | N10: 92 | O10: =ROUND((+G10*55%/8*2)*N10,0) -> 7653 | P10: 460 | Q10: 540 | R10: 0 | T10: =ROUND(K10+L10+O10+P10+Q10+R10+S10,0) -> 22568 | U10: =T10-L10 -> 16306 | V10: =ROUND(+K10*12%,0) -> 918 | W10: =CEILING(U10*0.75%,1) -> 123 | X10: 460 | AA10: =ROUND(T10-X10-Y10-V10-W10-Z10,0) -> 21067
A11: =A10+1 -> 8 | B11: 21872 | C11: CHINNASAMY CHINNAPALANI | D11: HK | G11: 605 | H11: 23 | I11: 0 | J11: =H11+I11 -> 23 | K11: =ROUND((G11*(J11))*55%,0) -> 7653 | L11: =ROUND((G11*(J11))*45%,0) -> 6262 | M11: =K11+L11 -> 13915 | N11: 22 | O11: =ROUND((+G11*55%/8*2)*N11,0) -> 1830 | P11: 0 | Q11: 1035 | R11: 0 | T11: =ROUND(K11+L11+O11+P11+Q11+R11+S11,0) -> 16780 | U11: =T11-L11 -> 10518 | V11: =ROUND(+K11*12%,0) -> 918 | W11: =CEILING(U11*0.75%,1) -> 79 | X11: 0 | AA11: =ROUND(T11-X11-Y11-V11-W11-Z11,0) -> 15783
A12: =A11+1 -> 9 | B12: 22042 | C12: GOVINDARAJ ARUMUGAM | D12: IMD | E12: IMD | G12: 605 | H12: 17 | I12: 0 | J12: =H12+I12 -> 17 | K12: =ROUND((G12*(J12))*55%,0) -> 5657 | L12: =ROUND((G12*(J12))*45%,0) -> 4628 | M12: =K12+L12 -> 10285 | N12: 68 | O12: =ROUND((+G12*55%/8*2)*N12,0) -> 5657 | P12: 340 | Q12: 270 | R12: 0 | T12: =ROUND(K12+L12+O12+P12+Q12+R12+S12,0) -> 16552 | U12: =T12-L12 -> 11924 | V12: =ROUND(+K12*12%,0) -> 679 | W12: =CEILING(U12*0.75%,1) -> 90 | X12: 340 | AA12: =ROUND(T12-X12-Y12-V12-W12-Z12,0) -> 15443
A13: =A12+1 -> 10 | B13: 22050 | C13: ANITHA SURESHMUTHU | D13: Assembly | E13: 101957103325 | F13: 5610062207 | G13: 605 | H13: 15 | I13: 0 | J13: =H13+I13 -> 15 | K13: =ROUND((G13*(J13))*55%,0) -> 4991 | L13: =ROUND((G13*(J13))*45%,0) -> 4084 | M13: =K13+L13 -> 9075 | N13: 0 | O13: =ROUND((+G13*55%/8*2)*N13,0) -> 0 | P13: 0 | Q13: 0 | R13: 0 | T13: =ROUND(K13+L13+O13+P13+Q13+R13+S13,0) -> 9075 | U13: =T13-L13 -> 4991 | V13: =ROUND(+K13*12%,0) -> 599 | W13: =CEILING(U13*0.75%,1) -> 38 | X13: 0 | AA13: =ROUND(T13-X13-Y13-V13-W13-Z13,0) -> 8438
A14: =A13+1 -> 11 | B14: 22104 | C14: VIJAYA LAKSHMI | D14: Assembly | E14: 101709340045 | F14: 5610992415 | G14: 605 | H14: 22 | I14: 0 | J14: =H14+I14 -> 22 | K14: =ROUND((G14*(J14))*55%,0) -> 7321 | L14: =ROUND((G14*(J14))*45%,0) -> 5990 | M14: =K14+L14 -> 13311 | N14: 0 | O14: =ROUND((+G14*55%/8*2)*N14,0) -> 0 | P14: 0 | Q14: 0 | R14: 0 | T14: =ROUND(K14+L14+O14+P14+Q14+R14+S14,0) -> 13311 | U14: =T14-L14 -> 7321 | V14: =ROUND(+K14*12%,0) -> 879 | W14: =CEILING(U14*0.75%,1) -> 55 | X14: 20 | AA14: =ROUND(T14-X14-Y14-V14-W14-Z14,0) -> 12357
A15: =A14+1 -> 12 | B15: 22111 | C15: INDHUMATHI | D15: Assembly | E15: 102085929890 | F15: 5610654825 | G15: 605 | H15: 20 | I15: 0 | J15: =H15+I15 -> 20 | K15: =ROUND((G15*(J15))*55%,0) -> 6655 | L15: =ROUND((G15*(J15))*45%,0) -> 5445 | M15: =K15+L15 -> 12100 | N15: 0 | O15: =ROUND((+G15*55%/8*2)*N15,0) -> 0 | P15: 0 | Q15: 0 | R15: 0 | T15: =ROUND(K15+L15+O15+P15+Q15+R15+S15,0) -> 12100 | U15: =T15-L15 -> 6655 | V15: =ROUND(+K15*12%,0) -> 799 | W15: =CEILING(U15*0.75%,1) -> 50 | X15: 0 | AA15: =ROUND(T15-X15-Y15-V15-W15-Z15,0) -> 11251
A16: =A15+1 -> 13 | B16: 22115 | C16: DEVI | D16: Assembly | E16: 101815134082 | F16: 5611011970 | G16: 605 | H16: 23 | I16: 0 | J16: =H16+I16 -> 23 | K16: =ROUND((G16*(J16))*55%,0) -> 7653 | L16: =ROUND((G16*(J16))*45%,0) -> 6262 | M16: =K16+L16 -> 13915 | N16: 0 | O16: =ROUND((+G16*55%/8*2)*N16,0) -> 0 | P16: 0 | Q16: 0 | R16: 0 | T16: =ROUND(K16+L16+O16+P16+Q16+R16+S16,0) -> 13915 | U16: =T16-L16 -> 7653 | V16: =ROUND(+K16*12%,0) -> 918 | W16: =CEILING(U16*0.75%,1) -> 58 | X16: 0 | AA16: =ROUND(T16-X16-Y16-V16-W16-Z16,0) -> 12939
A17: =A16+1 -> 14 | B17: 22133 | C17: RAMACHANDRAN | D17: AUTOMATION | G17: 605 | H17: 22 | I17: 0 | J17: =H17+I17 -> 22 | K17: =ROUND((G17*(J17))*55%,0) -> 7321 | L17: =ROUND((G17*(J17))*45%,0) -> 5990 | M17: =K17+L17 -> 13311 | N17: 88 | O17: =ROUND((+G17*55%/8*2)*N17,0) -> 7321 | P17: 440 | Q17: 495 | R17: 0 | T17: =ROUND(K17+L17+O17+P17+Q17+R17+S17,0) -> 21567 | U17: =T17-L17 -> 15577 | V17: =ROUND(+K17*12%,0) -> 879 | W17: =CEILING(U17*0.75%,1) -> 117 | X17: 220 | AA17: =ROUND(T17-X17-Y17-V17-W17-Z17,0) -> 20351
A18: =A17+1 -> 15 | B18: 22146 | C18: VASANTHAMNAI | D18: Fetling | G18: 605 | H18: 23 | I18: 0 | J18: =H18+I18 -> 23 | K18: =ROUND((G18*(J18))*55%,0) -> 7653 | L18: =ROUND((G18*(J18))*45%,0) -> 6262 | M18: =K18+L18 -> 13915 | N18: 0 | O18: =ROUND((+G18*55%/8*2)*N18,0) -> 0 | P18: 0 | Q18: 0 | R18: 0 | T18: =ROUND(K18+L18+O18+P18+Q18+R18+S18,0) -> 13915 | U18: =T18-L18 -> 7653 | V18: =ROUND(+K18*12%,0) -> 918 | W18: =CEILING(U18*0.75%,1) -> 58 | X18: 20 | AA18: =ROUND(T18-X18-Y18-V18-W18-Z18,0) -> 12919
A19: =A18+1 -> 16 | B19: 22149 | C19: DEEPA | D19: Assembly | G19: 605 | H19: 20 | I19: 0 | J19: =H19+I19 -> 20 | K19: =ROUND((G19*(J19))*55%,0) -> 6655 | L19: =ROUND((G19*(J19))*45%,0) -> 5445 | M19: =K19+L19 -> 12100 | N19: 0 | O19: =ROUND((+G19*55%/8*2)*N19,0) -> 0 | P19: 0 | Q19: 0 | R19: 0 | T19: =ROUND(K19+L19+O19+P19+Q19+R19+S19,0) -> 12100 | U19: =T19-L19 -> 6655 | V19: =ROUND(+K19*12%,0) -> 799 | W19: =CEILING(U19*0.75%,1) -> 50 | X19: 0 | AA19: =ROUND(T19-X19-Y19-V19-W19-Z19,0) -> 11251
A20: =A19+1 -> 17 | B20: 22176 | C20: HEMALATHA | D20: Assembly | G20: 605 | H20: 23 | I20: 0 | J20: =H20+I20 -> 23 | K20: =ROUND((G20*(J20))*55%,0) -> 7653 | L20: =ROUND((G20*(J20))*45%,0) -> 6262 | M20: =K20+L20 -> 13915 | N20: 0 | O20: =ROUND((+G20*55%/8*2)*N20,0) -> 0 | P20: 0 | Q20: 0 | R20: 0 | T20: =ROUND(K20+L20+O20+P20+Q20+R20+S20,0) -> 13915 | U20: =T20-L20 -> 7653 | V20: =ROUND(+K20*12%,0) -> 918 | W20: =CEILING(U20*0.75%,1) -> 58 | X20: 0 | AA20: =ROUND(T20-X20-Y20-V20-W20-Z20,0) -> 12939
A21: =A20+1 -> 18 | B21: 22215 | C21: SUNIL SAWAYNAM | D21: Assembly | G21: 605 | H21: 21 | I21: 0 | J21: =H21+I21 -> 21 | K21: =ROUND((G21*(J21))*55%,0) -> 6988 | L21: =ROUND((G21*(J21))*45%,0) -> 5717 | M21: =K21+L21 -> 12705 | N21: 89 | O21: =ROUND((+G21*55%/8*2)*N21,0) -> 7404 | P21: 400 | Q21: 0 | R21: 0 | T21: =ROUND(K21+L21+O21+P21+Q21+R21+S21,0) -> 20509 | U21: =T21-L21 -> 14792 | V21: =ROUND(+K21*12%,0) -> 839 | W21: =CEILING(U21*0.75%,1) -> 111 | X21: 460 | AA21: =ROUND(T21-X21-Y21-V21-W21-Z21,0) -> 19099
A22: =A21+1 -> 19 | B22: 22229 | C22: PREM KUMAR | D22: IMD | G22: 605 | H22: 10 | I22: 0 | J22: =H22+I22 -> 10 | K22: =ROUND((G22*(J22))*55%,0) -> 3328 | L22: =ROUND((G22*(J22))*45%,0) -> 2723 | M22: =K22+L22 -> 6051 | N22: 40 | O22: =ROUND((+G22*55%/8*2)*N22,0) -> 3328 | P22: 160 | Q22: 135 | R22: 0 | T22: =ROUND(K22+L22+O22+P22+Q22+R22+S22,0) -> 9674 | U22: =T22-L22 -> 6951 | V22: =ROUND(+K22*12%,0) -> 399 | W22: =CEILING(U22*0.75%,1) -> 53 | X22: 220 | AA22: =ROUND(T22-X22-Y22-V22-W22-Z22,0) -> 9002
A23: =A22+1 -> 20 | B23: 22232 | C23: MANOHAR KARAN | D23: IMD | G23: 605 | H23: 10 | I23: 0 | J23: =H23+I23 -> 10 | K23: =ROUND((G23*(J23))*55%,0) -> 3328 | L23: =ROUND((G23*(J23))*45%,0) -> 2723 | M23: =K23+L23 -> 6051 | N23: 40 | O23: =ROUND((+G23*55%/8*2)*N23,0) -> 3328 | P23: 200 | Q23: 225 | R23: 0 | T23: =ROUND(K23+L23+O23+P23+Q23+R23+S23,0) -> 9804 | U23: =T23-L23 -> 7081 | V23: =ROUND(+K23*12%,0) -> 399 | W23: =CEILING(U23*0.75%,1) -> 54 | X23: 180 | AA23: =ROUND(T23-X23-Y23-V23-W23-Z23,0) -> 9171
A24: =A23+1 -> 21 | B24: 22241 | C24: ANNALAKSHMI | D24: Assembly | G24: 605 | H24: 24 | I24: 0 | J24: =H24+I24 -> 24 | K24: =ROUND((G24*(J24))*55%,0) -> 7986 | L24: =ROUND((G24*(J24))*45%,0) -> 6534 | M24: =K24+L24 -> 14520 | N24: 0 | O24: =ROUND((+G24*55%/8*2)*N24,0) -> 0 | P24: 0 | Q24: 0 | R24: 0 | T24: =ROUND(K24+L24+O24+P24+Q24+R24+S24,0) -> 14520 | U24: =T24-L24 -> 7986 | V24: =ROUND(+K24*12%,0) -> 958 | W24: =CEILING(U24*0.75%,1) -> 60 | X24: 0 | AA24: =ROUND(T24-X24-Y24-V24-W24-Z24,0) -> 13502
A25: =A24+1 -> 22 | B25: 22242 | C25: SELVI S | D25: Assembly | G25: 605 | H25: 22 | I25: 0 | J25: =H25+I25 -> 22 | K25: =ROUND((G25*(J25))*55%,0) -> 7321 | L25: =ROUND((G25*(J25))*45%,0) -> 5990 | M25: =K25+L25 -> 13311 | N25: 0 | O25: =ROUND((+G25*55%/8*2)*N25,0) -> 0 | P25: 0 | Q25: 0 | R25: 0 | T25: =ROUND(K25+L25+O25+P25+Q25+R25+S25,0) -> 13311 | U25: =T25-L25 -> 7321 | V25: =ROUND(+K25*12%,0) -> 879 | W25: =CEILING(U25*0.75%,1) -> 55 | X25: 0 | AA25: =ROUND(T25-X25-Y25-V25-W25-Z25,0) -> 12377
A26: =A25+1 -> 23 | B26: 22265 | C26: PANDESWARAN | D26: Stores | G26: 605 | H26: 23 | I26: 0 | J26: =H26+I26 -> 23 | K26: =ROUND((G26*(J26))*55%,0) -> 7653 | L26: =ROUND((G26*(J26))*45%,0) -> 6262 | M26: =K26+L26 -> 13915 | N26: 100 | O26: =ROUND((+G26*55%/8*2)*N26,0) -> 8319 | P26: 460 | Q26: 0 | R26: 0 | T26: =ROUND(K26+L26+O26+P26+Q26+R26+S26,0) -> 22694 | U26: =T26-L26 -> 16432 | V26: =ROUND(+K26*12%,0) -> 918 | W26: =CEILING(U26*0.75%,1) -> 124 | X26: 460 | AA26: =ROUND(T26-X26-Y26-V26-W26-Z26,0) -> 21192
A27: =A26+1 -> 24 | B27: 22271 | C27: SURESH MARANDI | D27: AUTOMATION | G27: 605 | H27: 23 | I27: 0 | J27: =H27+I27 -> 23 | K27: =ROUND((G27*(J27))*55%,0) -> 7653 | L27: =ROUND((G27*(J27))*45%,0) -> 6262 | M27: =K27+L27 -> 13915 | N27: 92 | O27: =ROUND((+G27*55%/8*2)*N27,0) -> 7653 | P27: 460 | Q27: 540 | R27: 0 | T27: =ROUND(K27+L27+O27+P27+Q27+R27+S27,0) -> 22568 | U27: =T27-L27 -> 16306 | V27: =ROUND(+K27*12%,0) -> 918 | W27: =CEILING(U27*0.75%,1) -> 123 | X27: 460 | AA27: =ROUND(T27-X27-Y27-V27-W27-Z27,0) -> 21067
A28: =A27+1 -> 25 | B28: 22273 | C28: NUNULAL MURMU | D28: IMD | G28: 605 | H28: 21 | I28: 0 | J28: =H28+I28 -> 21 | K28: =ROUND((G28*(J28))*55%,0) -> 6988 | L28: =ROUND((G28*(J28))*45%,0) -> 5717 | M28: =K28+L28 -> 12705 | N28: 80 | O28: =ROUND((+G28*55%/8*2)*N28,0) -> 6655 | P28: 400 | Q28: 495 | R28: 0 | T28: =ROUND(K28+L28+O28+P28+Q28+R28+S28,0) -> 20255 | U28: =T28-L28 -> 14538 | V28: =ROUND(+K28*12%,0) -> 839 | W28: =CEILING(U28*0.75%,1) -> 110 | X28: 380 | AA28: =ROUND(T28-X28-Y28-V28-W28-Z28,0) -> 18926
... A43: =A42+1 -> 40 | B43: 22367 | C43: EKAMBAL | D43: Assembly | G43: 605 | H43: 22 | I43: 0 | J43: =H43+I43 -> 22 | K43: =ROUND((G43*(J43))*55%,0) -> 7321 | L43: =ROUND((G43*(J43))*45%,0) -> 5990 | M43: =K43+L43 -> 13311 | N43: 0 | O43: =ROUND((+G43*55%/8*2)*N43,0) -> 0 | P43: 0 | Q43: 0 | R43: 0 | T43: =ROUND(K43+L43+O43+P43+Q43+R43+S43,0) -> 13311 | U43: =T43-L43 -> 7321 | V43: =ROUND(+K43*12%,0) -> 879 | W43: =CEILING(U43*0.75%,1) -> 55 | X43: 0 | AA43: =ROUND(T43-X43-Y43-V43-W43-Z43,0) -> 12377
A44: =A43+1 -> 41 | B44: 22370 | C44: ROUTHROSCLINE | D44: Fetling | E44: Fetling | G44: 605 | H44: 8 | I44: 0 | J44: =H44+I44 -> 8 | K44: =ROUND((G44*(J44))*55%,0) -> 2662 | L44: =ROUND((G44*(J44))*45%,0) -> 2178 | M44: =K44+L44 -> 4840 | N44: 0 | O44: =ROUND((+G44*55%/8*2)*N44,0) -> 0 | P44: 0 | Q44: 0 | R44: 0 | T44: =ROUND(K44+L44+O44+P44+Q44+R44+S44,0) -> 4840 | U44: =T44-L44 -> 2662 | V44: =ROUND(+K44*12%,0) -> 319 | W44: =CEILING(U44*0.75%,1) -> 20 | X44: 0 | AA44: =ROUND(T44-X44-Y44-V44-W44-Z44,0) -> 4501
A45: =A44+1 -> 42 | B45: 22372 | C45: KARTHIKEYANI | D45: Assembly | E45: Assembly | G45: 605 | H45: 19 | I45: 0 | J45: =H45+I45 -> 19 | K45: =ROUND((G45*(J45))*55%,0) -> 6322 | L45: =ROUND((G45*(J45))*45%,0) -> 5173 | M45: =K45+L45 -> 11495 | N45: 0 | O45: =ROUND((+G45*55%/8*2)*N45,0) -> 0 | P45: 0 | Q45: 0 | R45: 0 | T45: =ROUND(K45+L45+O45+P45+Q45+R45+S45,0) -> 11495 | U45: =T45-L45 -> 6322 | V45: =ROUND(+K45*12%,0) -> 759 | W45: =CEILING(U45*0.75%,1) -> 48 | X45: 0 | AA45: =ROUND(T45-X45-Y45-V45-W45-Z45,0) -> 10688
A46: =A45+1 -> 43 | B46: 22373 | C46: SANJAY | D46: AUTOMATION | G46: 605 | H46: 22 | I46: 0 | J46: =H46+I46 -> 22 | K46: =ROUND((G46*(J46))*55%,0) -> 7321 | L46: =ROUND((G46*(J46))*45%,0) -> 5990 | M46: =K46+L46 -> 13311 | N46: 85 | O46: =ROUND((+G46*55%/8*2)*N46,0) -> 7071 | P46: 420 | Q46: 540 | R46: 0 | T46: =ROUND(K46+L46+O46+P46+Q46+R46+S46,0) -> 21342 | U46: =T46-L46 -> 15352 | V46: =ROUND(+K46*12%,0) -> 879 | W46: =CEILING(U46*0.75%,1) -> 116 | X46: 220 | AA46: =ROUND(T46-X46-Y46-V46-W46-Z46,0) -> 20127
A47: * | B47: * | C47: * | D47: * | E47: * | F47: * | G47: * | H47: =SUM(H4:H46) -> 880 | I47: =SUM(I4:I46) -> 0 | J47: =SUM(J4:J46) -> 880 | K47: =SUM(K4:K46) -> 292824 | L47: =SUM(L4:L46) -> 239585 | M47: =SUM(M4:M46) -> 532409 | N47: =SUM(N4:N46) -> 1346 | O47: =SUM(O4:O46) -> 111973 | ... AA47: =SUM(AA4:AA46) -> 613106

Sheet ROOM ALLOW
B2: OUTSIDE ROOM SEPTEMBER 2026
B3: S.NO | C3: CODE | D3: NAME | E3: DEPARTMENT | F3: ROOM ALLOW
B4: 1 | C4: 21713 | D4: MUNESHWAR SOREN | E4: IMD | F4: 250
B5: =B4+1 -> 2 | C5: 22215 | D5: SUNIL SAWAYNAM | E5: Assembly | F5: 250
B6: =B5+1 -> 3 | C6: 22271 | D6: SURESH MARANDI | E6: AUTOMATION | F6: 250
B7: =B6+1 -> 4 | C7: 22273 | D7: NUNULAL MURMU | E7: IMD | F7: 250
B8: =B7+1 -> 5 | C8: 22274 | D8: MAHAN MURMU | E8: IMD | F8: 250
B9: =B8+1 -> 6 | C9: 22277 | D9: ANTU SOREN | E9: IMD | F9: 250
B10: =B9+1 -> 7 | C10: 22279 | D10: SALMA SOREN | E10: Assembly | F10: 250
B11: =B10+1 -> 8 | C11: 22294 | D11: TRIDEV NAYAK | E11: Assembly | F11: 250
B12: =B11+1 -> 9 | C12: 22295 | D12: SONY CHAMPIYA | E12: Assembly | F12: 250
B13: =B12+1 -> 10 | C13: 22325 | D13: MUNKIDEVI | E13: Assembly | F13: 250
B14: =B13+1 -> 11 | C14: 22330 | D14: SURESH KINDO | E14: Assembly | F14: 250
B15: =B14+1 -> 12 | C15: 22341 | D15: KUNAL UMAR TURI | E15: IMD | F15: 250
B16: =B15+1 -> 13 | C16: 22345 | D16: MUNNA SOREN | E16: IMD | F16: 250
... B20: =B19+1 -> 17 | C20: 22362 | D20: MINAKSHI KUMARI | E20: Fetling | F20: 250
F21: =SUM(F4:F20) -> 4250

Sheet DEC'25
